<?xml version='1.0'?>
<sdf version='1.6'>
	<model name='vehicle_lidar'>
		<link name='link_0'>
			<pose frame=''>-0.091777 0.002441 0.019551 0 -0 0</pose>
			<inertial>
				<mass>0.234374</mass>
				<inertia>
					<ixx>0.00967632</ixx>
					<ixy>0</ixy>
					<ixz>0</ixz>
					<iyy>0.0227053</iyy>
					<iyz>0</iyz>
					<izz>0.022084</izz>
				</inertia>
				<pose frame=''>0 0 0 0 -0 0</pose>
			</inertial>
			<self_collide>0</self_collide>
			<kinematic>0</kinematic>
			<visual name='visual'>
				<pose frame=''>0 0 0 0 -0 0</pose>
				<geometry>
					<box>
						<size>0.948099 0.481462 0.513452</size>
					</box>
				</geometry>
				<material>
					<lighting>1</lighting>
					<script>
						<uri>file://media/materials/scripts/gazebo.material</uri>
						<name>Gazebo/Grey</name>
					</script>
					<ambient>0.3 0.3 0.3 1</ambient>
					<diffuse>0.7 0.7 0.7 1</diffuse>
					<specular>0.01 0.01 0.01 1</specular>
					<emissive>0 0 0 1</emissive>
					<shader type='vertex'>
						<normal_map>__default__</normal_map>
					</shader>
				</material>
				<cast_shadows>1</cast_shadows>
				<transparency>0</transparency>
			</visual>
			<collision name='collision'>
				<laser_retro>0</laser_retro>
				<max_contacts>10</max_contacts>
				<pose frame=''>0 0 0 0 -0 0</pose>
				<geometry>
					<box>
						<size>0.948099 0.481462 0.513452</size>
					</box>
				</geometry>
				<surface>
					<friction>
						<ode>
							<mu>1</mu>
							<mu2>1</mu2>
							<fdir1>0 0 0</fdir1>
							<slip1>0</slip1>
							<slip2>0</slip2>
						</ode>
						<torsional>
							<coefficient>1</coefficient>
							<patch_radius>0</patch_radius>
							<surface_radius>0</surface_radius>
							<use_patch_radius>1</use_patch_radius>
							<ode>
								<slip>0</slip>
							</ode>
						</torsional>
					</friction>
					<bounce>
						<restitution_coefficient>0</restitution_coefficient>
						<threshold>1e+06</threshold>
					</bounce>
					<contact>
						<collide_without_contact>0</collide_without_contact>
						<collide_without_contact_bitmask>1</collide_without_contact_bitmask>
						<collide_bitmask>1</collide_bitmask>
						<ode>
							<soft_cfm>0</soft_cfm>
							<soft_erp>0.2</soft_erp>
							<kp>1e+13</kp>
							<kd>1</kd>
							<max_vel>0.01</max_vel>
							<min_depth>0</min_depth>
						</ode>
						<bullet>
							<split_impulse>1</split_impulse>
							<split_impulse_penetration_threshold>-0.01</split_impulse_penetration_threshold>
							<soft_cfm>0</soft_cfm>
							<soft_erp>0.2</soft_erp>
							<kp>1e+13</kp>
							<kd>1</kd>
						</bullet>
					</contact>
				</surface>
			</collision>
		</link>
		<link name='link_1'>
			<pose frame=''>0.082272 -0.363319 -0.080449 1.5707 -0 0</pose>
			<inertial>
				<mass>1</mass>
				<inertia>
					<ixx>0.145833</ixx>
					<ixy>0</ixy>
					<ixz>0</ixz>
					<iyy>0.145833</iyy>
					<iyz>0</iyz>
					<izz>0.125</izz>
				</inertia>
				<pose frame=''>0 0 0 0 -0 0</pose>
			</inertial>
			<self_collide>0</self_collide>
			<kinematic>0</kinematic>
			<visual name='visual'>
				<pose frame=''>0 0 0 0 -0 0</pose>
				<geometry>
					<cylinder>
						<radius>0.3</radius>
						<length>0.25</length>
					</cylinder>
				</geometry>
				<material>
					<lighting>1</lighting>
					<script>
						<uri>file://media/materials/scripts/gazebo.material</uri>
						<name>Gazebo/Grey</name>
					</script>
					<ambient>0.3 0.3 0.3 1</ambient>
					<diffuse>0.7 0.7 0.7 1</diffuse>
					<specular>0.01 0.01 0.01 1</specular>
					<emissive>0 0 0 1</emissive>
					<shader type='vertex'>
						<normal_map>__default__</normal_map>
					</shader>
				</material>
				<cast_shadows>1</cast_shadows>
				<transparency>0</transparency>
			</visual>
			<collision name='collision'>
				<laser_retro>0</laser_retro>
				<max_contacts>10</max_contacts>
				<pose frame=''>0 0 0 0 -0 0</pose>
				<geometry>
					<cylinder>
						<radius>0.3</radius>
						<length>0.25</length>
					</cylinder>
				</geometry>
				<surface>
					<friction>
						<ode>
							<mu>1</mu>
							<mu2>1</mu2>
							<fdir1>0 0 0</fdir1>
							<slip1>0</slip1>
							<slip2>0</slip2>
						</ode>
						<torsional>
							<coefficient>1</coefficient>
							<patch_radius>0</patch_radius>
							<surface_radius>0</surface_radius>
							<use_patch_radius>1</use_patch_radius>
							<ode>
								<slip>0</slip>
							</ode>
						</torsional>
					</friction>
					<bounce>
						<restitution_coefficient>0</restitution_coefficient>
						<threshold>1e+06</threshold>
					</bounce>
					<contact>
						<collide_without_contact>0</collide_without_contact>
						<collide_without_contact_bitmask>1</collide_without_contact_bitmask>
						<collide_bitmask>1</collide_bitmask>
						<ode>
							<soft_cfm>0</soft_cfm>
							<soft_erp>0.2</soft_erp>
							<kp>1e+13</kp>
							<kd>1</kd>
							<max_vel>0.01</max_vel>
							<min_depth>0</min_depth>
						</ode>
						<bullet>
							<split_impulse>1</split_impulse>
							<split_impulse_penetration_threshold>-0.01</split_impulse_penetration_threshold>
							<soft_cfm>0</soft_cfm>
							<soft_erp>0.2</soft_erp>
							<kp>1e+13</kp>
							<kd>1</kd>
						</bullet>
					</contact>
				</surface>
			</collision>
		</link>
		<link name='link_1_clone'>
			<pose frame=''>0.082272 0.368201 -0.080449 1.5707 -0 0</pose>
			<inertial>
				<mass>1</mass>
				<inertia>
					<ixx>0.145833</ixx>
					<ixy>0</ixy>
					<ixz>0</ixz>
					<iyy>0.145833</iyy>
					<iyz>0</iyz>
					<izz>0.125</izz>
				</inertia>
				<pose frame=''>0 0 0 0 -0 0</pose>
			</inertial>
			<self_collide>0</self_collide>
			<kinematic>0</kinematic>
			<visual name='visual'>
				<pose frame=''>0 0 0 0 -0 0</pose>
				<geometry>
					<cylinder>
						<radius>0.3</radius>
						<length>0.25</length>
					</cylinder>
				</geometry>
				<material>
					<lighting>1</lighting>
					<script>
						<uri>file://media/materials/scripts/gazebo.material</uri>
						<name>Gazebo/Grey</name>
					</script>
					<ambient>0.3 0.3 0.3 1</ambient>
					<diffuse>0.7 0.7 0.7 1</diffuse>
					<specular>0.01 0.01 0.01 1</specular>
					<emissive>0 0 0 1</emissive>
					<shader type='vertex'>
						<normal_map>__default__</normal_map>
					</shader>
				</material>
				<cast_shadows>1</cast_shadows>
				<transparency>0</transparency>
			</visual>
			<collision name='collision'>
				<laser_retro>0</laser_retro>
				<max_contacts>10</max_contacts>
				<pose frame=''>0 0 0 0 -0 0</pose>
				<geometry>
					<cylinder>
						<radius>0.3</radius>
						<length>0.25</length>
					</cylinder>
				</geometry>
				<surface>
					<friction>
						<ode>
							<mu>1</mu>
							<mu2>1</mu2>
							<fdir1>0 0 0</fdir1>
							<slip1>0</slip1>
							<slip2>0</slip2>
						</ode>
						<torsional>
							<coefficient>1</coefficient>
							<patch_radius>0</patch_radius>
							<surface_radius>0</surface_radius>
							<use_patch_radius>1</use_patch_radius>
							<ode>
								<slip>0</slip>
							</ode>
						</torsional>
					</friction>
					<bounce>
						<restitution_coefficient>0</restitution_coefficient>
						<threshold>1e+06</threshold>
					</bounce>
					<contact>
						<collide_without_contact>0</collide_without_contact>
						<collide_without_contact_bitmask>1</collide_without_contact_bitmask>
						<collide_bitmask>1</collide_bitmask>
						<ode>
							<soft_cfm>0</soft_cfm>
							<soft_erp>0.2</soft_erp>
							<kp>1e+13</kp>
							<kd>1</kd>
							<max_vel>0.01</max_vel>
							<min_depth>0</min_depth>
						</ode>
						<bullet>
							<split_impulse>1</split_impulse>
							<split_impulse_penetration_threshold>-0.01</split_impulse_penetration_threshold>
							<soft_cfm>0</soft_cfm>
							<soft_erp>0.2</soft_erp>
							<kp>1e+13</kp>
							<kd>1</kd>
						</bullet>
					</contact>
				</surface>
			</collision>
		</link>
		<link name='link_2'>
			<pose frame=''>-0.365826 0.002441 -0.180449 0 -0 0</pose>
			<inertial>
				<mass>1</mass>
				<inertia>
					<ixx>0.1</ixx>
					<ixy>0</ixy>
					<ixz>0</ixz>
					<iyy>0.1</iyy>
					<iyz>0</iyz>
					<izz>0.1</izz>
				</inertia>
				<pose frame=''>0 0 0 0 -0 0</pose>
			</inertial>
			<self_collide>0</self_collide>
			<kinematic>0</kinematic>
			<visual name='visual'>
				<pose frame=''>0 0 0 0 -0 0</pose>
				<geometry>
					<sphere>
						<radius>0.2</radius>
					</sphere>
				</geometry>
				<material>
					<lighting>1</lighting>
					<script>
						<uri>file://media/materials/scripts/gazebo.material</uri>
						<name>Gazebo/Grey</name>
					</script>
					<ambient>0.3 0.3 0.3 1</ambient>
					<diffuse>0.7 0.7 0.7 1</diffuse>
					<specular>0.01 0.01 0.01 1</specular>
					<emissive>0 0 0 1</emissive>
					<shader type='vertex'>
						<normal_map>__default__</normal_map>
					</shader>
				</material>
				<cast_shadows>1</cast_shadows>
				<transparency>0</transparency>
			</visual>
			<collision name='collision'>
				<laser_retro>0</laser_retro>
				<max_contacts>10</max_contacts>
				<pose frame=''>0 0 0 0 -0 0</pose>
				<geometry>
					<sphere>
						<radius>0.2</radius>
					</sphere>
				</geometry>
				<surface>
					<friction>
						<ode>
							<mu>1</mu>
							<mu2>1</mu2>
							<fdir1>0 0 0</fdir1>
							<slip1>0</slip1>
							<slip2>0</slip2>
						</ode>
						<torsional>
							<coefficient>1</coefficient>
							<patch_radius>0</patch_radius>
							<surface_radius>0</surface_radius>
							<use_patch_radius>1</use_patch_radius>
							<ode>
								<slip>0</slip>
							</ode>
						</torsional>
					</friction>
					<bounce>
						<restitution_coefficient>0</restitution_coefficient>
						<threshold>1e+06</threshold>
					</bounce>
					<contact>
						<collide_without_contact>0</collide_without_contact>
						<collide_without_contact_bitmask>1</collide_without_contact_bitmask>
						<collide_bitmask>1</collide_bitmask>
						<ode>
							<soft_cfm>0</soft_cfm>
							<soft_erp>0.2</soft_erp>
							<kp>1e+13</kp>
							<kd>1</kd>
							<max_vel>0.01</max_vel>
							<min_depth>0</min_depth>
						</ode>
						<bullet>
							<split_impulse>1</split_impulse>
							<split_impulse_penetration_threshold>-0.01</split_impulse_penetration_threshold>
							<soft_cfm>0</soft_cfm>
							<soft_erp>0.2</soft_erp>
							<kp>1e+13</kp>
							<kd>1</kd>
						</bullet>
					</contact>
				</surface>
			</collision>
		</link>
		<model name='hokuyo'>
			<link name='link'>
				<gravity>0</gravity>
				<inertial>
					<mass>0.0001</mass>
					<inertia>
						<ixx>1</ixx>
						<ixy>0</ixy>
						<ixz>0</ixz>
						<iyy>1</iyy>
						<iyz>0</iyz>
						<izz>1</izz>
					</inertia>
				</inertial>
				<visual name='visual'>
					<geometry>
						<mesh>
							<uri>model://hokuyo/meshes/hokuyo.dae</uri>
						</mesh>
					</geometry>
				</visual>
				<sensor name='laser' type='ray'>
					<pose frame=''>0.01 0 0.03 0 -0 0</pose>
					<ray>
						<scan>
							<horizontal>
								<samples>360</samples>
								<resolution>1</resolution>
								<min_angle>-3.12414</min_angle>
								<max_angle>3.12414</max_angle>
							</horizontal>
							<vertical>
								<samples>1</samples>
								<min_angle>0</min_angle>
								<max_angle>0</max_angle>
							</vertical>
						</scan>
						<range>
							<min>0.08</min>
							<max>10</max>
							<resolution>0.01</resolution>
						</range>
					</ray>
					<plugin name='gazebo_ros_head_hokuyo_controller' filename='libgazebo_ros_laser.so'>
						<topicName>/rrbot/laser/scan</topicName>
						<frameName>hokuyo_link</frameName>
					</plugin>
					<always_on>1</always_on>
					<update_rate>30</update_rate>
					<visualize>1</visualize>
				</sensor>
				<self_collide>0</self_collide>
				<kinematic>0</kinematic>
			</link>
			<pose frame=''>0.293058 -0.009765 0.321797 0 -0 0</pose>
		</model>
		<joint name='link_0_JOINT_0' type='revolute'>
			<parent>link_0</parent>
			<child>link_1</child>
			<pose frame=''>0 0 0 0 -0 0</pose>
			<axis>
				<xyz>0 0 -1</xyz>
				<use_parent_model_frame>0</use_parent_model_frame>
				<limit>
					<lower>-1.79769e+308</lower>
					<upper>1.79769e+308</upper>
					<effort>-1</effort>
					<velocity>-1</velocity>
				</limit>
				<dynamics>
					<spring_reference>0</spring_reference>
					<spring_stiffness>0</spring_stiffness>
					<damping>0</damping>
					<friction>0</friction>
				</dynamics>
			</axis>
			<physics>
				<ode>
					<limit>
						<cfm>0</cfm>
						<erp>0.2</erp>
					</limit>
					<suspension>
						<cfm>0</cfm>
						<erp>0.2</erp>
					</suspension>
				</ode>
			</physics>
		</joint>
		<joint name='link_0_JOINT_1' type='revolute'>
			<parent>link_0</parent>
			<child>link_1_clone</child>
			<pose frame=''>0 0 0 0 -0 0</pose>
			<axis>
				<xyz>0 0 1</xyz>
				<use_parent_model_frame>0</use_parent_model_frame>
				<limit>
					<lower>-1.79769e+308</lower>
					<upper>1.79769e+308</upper>
					<effort>-1</effort>
					<velocity>-1</velocity>
				</limit>
				<dynamics>
					<spring_reference>0</spring_reference>
					<spring_stiffness>0</spring_stiffness>
					<damping>0</damping>
					<friction>0</friction>
				</dynamics>
			</axis>
			<physics>
				<ode>
					<limit>
						<cfm>0</cfm>
						<erp>0.2</erp>
					</limit>
					<suspension>
						<cfm>0</cfm>
						<erp>0.2</erp>
					</suspension>
				</ode>
			</physics>
		</joint>
		<joint name='link_0_JOINT_2' type='ball'>
			<parent>link_0</parent>
			<child>link_2</child>
			<pose frame=''>0 0 0 0 -0 0</pose>
			<physics>
				<ode>
					<limit>
						<cfm>0</cfm>
						<erp>0.2</erp>
					</limit>
					<suspension>
						<cfm>0</cfm>
						<erp>0.2</erp>
					</suspension>
				</ode>
			</physics>
		</joint>
		<joint name='link_0_JOINT_3' type='fixed'>
			<parent>link_0</parent>
			<child>hokuyo::link</child>
			<pose frame=''>0 0 0 0 -0 0</pose>
			<physics>
				<ode>
					<limit>
						<cfm>0</cfm>
						<erp>0.2</erp>
					</limit>
					<suspension>
						<cfm>0</cfm>
						<erp>0.2</erp>
					</suspension>
				</ode>
			</physics>
		</joint>
		<static>0</static>
		<allow_auto_disable>1</allow_auto_disable>

		<plugin name="differential_drive_controller" filename="libgazebo_ros_diff_drive.so">
			<alwaysOn>true</alwaysOn>
			<legacyMode>true</legacyMode>
			<updateRate>30</updateRate>
			<leftJoint>link_0_JOINT_0</leftJoint>
			<rightJoint>link_0_JOINT_1</rightJoint>
			<wheelSeparation>0.73146</wheelSeparation>
			<wheelDiameter>0.6</wheelDiameter>
			<torque>20</torque>
			<commandTopic>cmd_vel</commandTopic>
			<odometryTopic>odom</odometryTopic>
			<odometryFrame>odom</odometryFrame>
			<robotBaseFrame>link_0</robotBaseFrame>
		</plugin>
	</model>
</sdf>
